<?xml version="1.0" ?>
<!-- =================================================================================== -->
<!-- |    This document was autogenerated by xacro from ./dx_system/dx_launch/description/0x02000105.urdf.xacro | -->
<!-- |    EDITING THIS FILE BY HAND IS NOT RECOMMENDED                                 | -->
<!-- =================================================================================== -->
<!--
 Software License Agreement (BSD License)
 Copyright © 2024-2025 belongs to Shadow Robot Company Ltd.
 All rights reserved.
 Redistribution and use in source and binary forms, with or without modification,
 are permitted provided that the following conditions are met:
   1. Redistributions of source code must retain the above copyright notice,
      this list of conditions and the following disclaimer.
   2. Redistributions in binary form must reproduce the above copyright notice,
      this list of conditions and the following disclaimer in the documentation
      and/or other materials provided with the distribution.
   3. Neither the name of Shadow Robot Company Ltd nor the names of its contributors
      may be used to endorse or promote products derived from this software without
      specific prior written permission.
 This software is provided by Shadow Robot Company Ltd "as is" and any express
 or implied warranties, including, but not limited to, the implied warranties of
 merchantability and fitness for a particular purpose are disclaimed. In no event
 shall the copyright holder be liable for any direct, indirect, incidental, special,
 exemplary, or consequential damages (including, but not limited to, procurement of
 substitute goods or services; loss of use, data, or profits; or business interruption)
 however caused and on any theory of liability, whether in contract, strict liability,
 or tort (including negligence or otherwise) arising in any way out of the use of this
 software, even if advised of the possibility of such damage.
-->
<robot name="e3_r3_hand">

  <link name="world"/>
    <!-- Six virtual links (massless, no geometry) -->
  <link name="link_1">
    <inertial>
      <mass value="0.0"/>
      <inertia ixx="0" ixy="0" ixz="0" iyy="0" iyz="0" izz="0"/>
    </inertial>
  </link>
  <link name="link_2">
    <inertial>
      <mass value="0.0"/>
      <inertia ixx="0" ixy="0" ixz="0" iyy="0" iyz="0" izz="0"/>
    </inertial>
  </link>
  <link name="link_3">
    <inertial>
      <mass value="0.0"/>
      <inertia ixx="0" ixy="0" ixz="0" iyy="0" iyz="0" izz="0"/>
    </inertial>
  </link>
  <link name="link_4">
    <inertial>
      <mass value="0.0"/>
      <inertia ixx="0" ixy="0" ixz="0" iyy="0" iyz="0" izz="0"/>
    </inertial>
  </link>
  <link name="link_5">
    <inertial>
      <mass value="0.0"/>
      <inertia ixx="0" ixy="0" ixz="0" iyy="0" iyz="0" izz="0"/>
    </inertial>
  </link>

  <!-- Joints (alternating prismatic and revolute) -->
  <joint name="joint_1_prismatic_z" type="prismatic">
    <parent link="world"/>
    <child  link="link_1"/>
    <origin xyz="0 0 0" rpy="0 0 0"/>
    <axis xyz="0 0 1"/>
    <limit lower="-0.2" upper="0.2" effort="10" velocity="0.5"/>
  </joint>

  <joint name="joint_2_revolute_z" type="revolute">
    <parent link="link_1"/>
    <child  link="link_2"/>
    <origin xyz="0 0 0" rpy="0 0 0"/>
    <axis xyz="0 0 1"/>
    <limit lower="-3.14" upper="3.14" effort="10" velocity="1"/>
  </joint>

  <joint name="joint_3_prismatic_x" type="prismatic">
    <parent link="link_2"/>
    <child  link="link_3"/>
    <origin xyz="0 0 0" rpy="0 0 0"/>
    <axis xyz="1 0 0"/>
    <limit lower="0.0" upper="0.3" effort="10" velocity="0.5"/>
  </joint>

  <joint name="joint_4_revolute_y" type="revolute">
    <parent link="link_3"/>
    <child  link="link_4"/>
    <origin xyz="0 0 0" rpy="0 0 0"/>
    <axis xyz="0 1 0"/>
    <limit lower="-1.57" upper="1.57" effort="10" velocity="1"/>
  </joint>

  <joint name="joint_5_prismatic_x" type="prismatic">
    <parent link="link_4"/>
    <child  link="link_5"/>
    <origin xyz="0 0 0" rpy="0 0 0"/>
    <axis xyz="1 0 0"/>
    <limit lower="0.0" upper="0.2" effort="10" velocity="0.5"/>
  </joint>

  <joint name="joint_6_revolute_z" type="revolute">
    <parent link="link_5"/>
    <child  link="hand_base"/>
    <origin xyz="0 0 0" rpy="0 0 0"/>
    <axis xyz="0 0 1"/>
    <limit lower="-3.14" upper="3.14" effort="10" velocity="1"/>
  </joint>

  <link name="hand_base">
    <inertial>
      <origin rpy="0 0 0" xyz="0.00024269 0.0064896 0.05011689"/>
      <mass value="0.53506724"/>
      <inertia ixx="0.00235606" ixy="-0.00000318" ixz="0.00001251" iyy="0.00262644" iyz="-0.00010584" izz="0.00095084"/>
    </inertial>
    <visual>
      <origin rpy="0 0 0" xyz="0 0 0"/>
      <geometry>
        <mesh filename="meshes/Hand_Base.dae"/>
      </geometry>
      <material name="">
        <color rgba="0.898039215686275 0.917647058823529 0.929411764705882 1"/>
      </material>
    </visual>
    <collision>
      <origin rpy="0 0 0" xyz="0 0 0"/>
      <geometry>
        <mesh filename="meshes/collision/Hand_Base.stl"/>
      </geometry>
    </collision>
  </link>
  <gazebo reference="hand_base">
    <selfCollide>true</selfCollide>
  </gazebo>
  <!-- Create a virtual end effector link that will be useful for arm IK -->
  <link name="end_effector"/>
  <joint name="ee_fixed_joint" type="fixed">
    <parent link="hand_base"/>
    <child link="end_effector"/>
    <origin rpy="0.0 0.0 0.0" xyz="0.0 0.0 0.25"/>
  </joint>
  <joint name="world_joint_F0" type="fixed">
    <origin rpy="-1.5707 0 0" xyz="0 0.05 0.017"/>
    <parent link="hand_base"/>
    <child link="F0_base"/>
  </joint>
  <link name="F0_base">
    <inertial>
      <origin rpy="0 0 0" xyz="0.00004454 0.00736569 0.08093736"/>
      <mass value="0.89937782"/>
      <inertia ixx="0.00186283" ixy="-0.00000176" ixz="-0.00000296" iyy="0.00181365" iyz="0.00004212" izz="0.00058221"/>
    </inertial>
    <visual>
      <origin rpy="1.5707 0 0" xyz="0 0 0"/>
      <geometry>
        <mesh filename="meshes/F0_base.dae"/>
      </geometry>
      <material name="">
        <color rgba="0.75294 0.75294 0.75294 1"/>
      </material>
    </visual>
    <collision>
      <origin rpy="1.5707 0 0" xyz="0 0 0"/>
      <geometry>
        <mesh filename="meshes/collision/F0_base.stl"/>
      </geometry>
    </collision>
  </link>
  <gazebo reference="F0_base">
    <selfCollide>true</selfCollide>
  </gazebo>
  <link name="F0_J0_link">
    <inertial>
      <origin rpy="0 0 0" xyz="-0.00017293 -0.01537184 0.00956679"/>
      <mass value="0.13077995"/>
      <inertia ixx="0.00005895" ixy="0.00000007" ixz="0.00000064" iyy="0.00004702" iyz="-0.00000971" izz="0.00003911"/>
    </inertial>
    <visual>
      <origin rpy="0 0 0" xyz="0 0.077 0"/>
      <geometry>
        <mesh filename="meshes/F0_J0_link.dae"/>
      </geometry>
      <material name="">
        <color rgba="0.75294 0.75294 0.75294 1"/>
      </material>
    </visual>
    <collision>
      <origin rpy="0 0 0" xyz="0 0.077 0"/>
      <geometry>
        <mesh filename="meshes/collision/F0_J0_link.stl"/>
      </geometry>
    </collision>
  </link>
  <gazebo reference="F0_J0_link">
    <selfCollide>true</selfCollide>
  </gazebo>
  <joint name="F0_J0" type="revolute">
    <origin rpy="2.0944 0 0" xyz="0 -0.14073 -0.051327"/>
    <parent link="F0_base"/>
    <child link="F0_J0_link"/>
    <axis xyz="0 -1 0"/>
    <limit effort="1.5" lower="-0.8727" upper="0.8727" velocity="3.1415"/>
    <dynamics friction="0.001"/>
  </joint>
  <link name="F0_proximal">
    <inertial>
      <origin rpy="0 0 0" xyz="-0.00020256 0.0024322 0.02375091"/>
      <mass value="0.09614332"/>
      <inertia ixx="0.00004332" ixy="-0.00000017" ixz="-0.00000349" iyy="0.00004756" iyz="0.00000055" izz="0.00002008"/>
    </inertial>
    <visual>
      <origin rpy="0 0 0" xyz="0 0 0"/>
      <geometry>
        <mesh filename="meshes/F0_proximal.dae"/>
      </geometry>
      <material name="">
        <color rgba="0.75294 0.75294 0.75294 1"/>
      </material>
    </visual>
    <collision>
      <origin rpy="0 0 0" xyz="0 0 0"/>
      <geometry>
        <mesh filename="meshes/collision/F0_proximal.stl"/>
      </geometry>
    </collision>
  </link>
  <gazebo reference="F0_proximal">
    <selfCollide>true</selfCollide>
  </gazebo>
  <joint name="F0_J1" type="revolute">
    <origin rpy="0 0 0" xyz="0 0.0765883365730207 0.0299999999999999"/>
    <parent link="F0_J0_link"/>
    <child link="F0_proximal"/>
    <axis xyz="1 0 0"/>
    <limit effort="1.2" lower="-1.396" upper="0.785" velocity="3.1415"/>
    <dynamics friction="0.001"/>
  </joint>
  <link name="F0_middle">
    <inertial>
      <origin rpy="0 0 0" xyz="-0.00026744 -0.00004338 0.01669764"/>
      <mass value="0.05585897"/>
      <inertia ixx="0.00001447" ixy="-0.00000005" ixz="-0.00000004" iyy="0.00001686" iyz="-0.00000007" izz="0.00000973"/>
    </inertial>
    <visual>
      <origin rpy="0 0 0" xyz="0 0 0"/>
      <geometry>
        <mesh filename="meshes/F0_middle.dae"/>
      </geometry>
      <material name="">
        <color rgba="0.75294 0.75294 0.75294 1"/>
      </material>
    </visual>
    <collision>
      <origin rpy="0 0 0" xyz="0 0 0"/>
      <geometry>
        <mesh filename="meshes/collision/F0_middle.stl"/>
      </geometry>
    </collision>
  </link>
  <gazebo reference="F0_middle">
    <selfCollide>true</selfCollide>
  </gazebo>
  <joint name="F0_J2" type="revolute">
    <origin rpy="0 0 0" xyz="0 0 0.05"/>
    <parent link="F0_proximal"/>
    <child link="F0_middle"/>
    <axis xyz="1 0 0"/>
    <limit effort="0.7" lower="0" upper="1.396" velocity="3.1415"/>
    <dynamics friction="0.001"/>
  </joint>
  <link name="F0_distal">
    <inertial>
      <origin rpy="0 0 0" xyz="0.00084325 0.00164346 0.01482169"/>
      <mass value="0.02766365"/>
      <inertia ixx="0.0000051" ixy="0" ixz="0.00000028" iyy="0.00000506" iyz="-0.00000034" izz="0.00000198"/>
    </inertial>
    <visual>
      <origin rpy="0 0 0" xyz="0 0 0"/>
      <geometry>
        <mesh filename="meshes/F0_distal.dae"/>
      </geometry>
      <material name="">
        <color rgba="0.75294 0.75294 0.75294 1"/>
      </material>
    </visual>
    <collision>
      <origin rpy="0 0 0" xyz="0 0 0"/>
      <geometry>
        <mesh filename="meshes/collision/F0_distal.stl"/>
      </geometry>
    </collision>
  </link>
  <gazebo reference="F0_distal">
    <selfCollide>true</selfCollide>
  </gazebo>
  <joint name="F0_J3" type="revolute">
    <origin rpy="0 0 0" xyz="0 0 0.035"/>
    <parent link="F0_middle"/>
    <child link="F0_distal"/>
    <axis xyz="1 0 0"/>
    <limit effort="0.35" lower="-0.523" upper="1.485" velocity="3.1415"/>
    <dynamics friction="0.001"/>
  </joint>
  <link name="F0_tip"/>
  <joint name="F0_distal_tip" type="fixed">
    <parent link="F0_distal"/>
    <child link="F0_tip"/>
    <origin rpy="0 0 0" xyz="0 0.003 0.033"/>
  </joint>
  <!-- These transmissions are wrongly configured and fail to be loaded by the real robot -->
  <!-- We still need to define them in order to be able to launch the robot in simulation -->
  <transmission name="trans_F0_J0">
    <type>UnusedTransmission</type>
    <joint name="F0_J0">
      <hardwareInterface>hardware_interface/EffortJointInterface</hardwareInterface>
    </joint>
    <actuator name="F0_J0_motor">
      <!-- <hardwareInterface>hardware_interface/EffortJointInterface</hardwareInterface> -->
      <mechanicalReduction>1</mechanicalReduction>
    </actuator>
  </transmission>
  <transmission name="trans_F0_J1">
    <type>UnusedTransmission</type>
    <joint name="F0_J1">
      <hardwareInterface>hardware_interface/EffortJointInterface</hardwareInterface>
    </joint>
    <actuator name="F0_J1_motor">
      <!-- <hardwareInterface>hardware_interface/EffortJointInterface</hardwareInterface> -->
      <mechanicalReduction>1</mechanicalReduction>
    </actuator>
  </transmission>
  <transmission name="trans_F0_J2">
    <type>UnusedTransmission</type>
    <joint name="F0_J2">
      <hardwareInterface>hardware_interface/EffortJointInterface</hardwareInterface>
    </joint>
    <actuator name="F0_J2_motor">
      <!-- <hardwareInterface>hardware_interface/EffortJointInterface</hardwareInterface> -->
      <mechanicalReduction>1</mechanicalReduction>
    </actuator>
  </transmission>
  <transmission name="trans_F0_J3">
    <type>UnusedTransmission</type>
    <joint name="F0_J3">
      <hardwareInterface>hardware_interface/EffortJointInterface</hardwareInterface>
    </joint>
    <actuator name="F0_J3_motor">
      <!-- <hardwareInterface>hardware_interface/EffortJointInterface</hardwareInterface> -->
      <mechanicalReduction>1</mechanicalReduction>
    </actuator>
  </transmission>
  <joint name="world_joint_F1" type="fixed">
    <origin rpy="-1.5707 0 -2.8159" xyz="0.0384 -0.0287 0.017"/>
    <parent link="hand_base"/>
    <child link="F1_base"/>
  </joint>
  <link name="F1_base">
    <inertial>
      <origin rpy="0 0 0" xyz="0.00004454 0.00736569 0.08093736"/>
      <mass value="0.89937782"/>
      <inertia ixx="0.00186283" ixy="-0.00000176" ixz="-0.00000296" iyy="0.00181365" iyz="0.00004212" izz="0.00058221"/>
    </inertial>
    <visual>
      <origin rpy="1.5707 0 0" xyz="0 0 0"/>
      <geometry>
        <mesh filename="meshes/F0_base.dae"/>
      </geometry>
      <material name="">
        <color rgba="0.75294 0.75294 0.75294 1"/>
      </material>
    </visual>
    <collision>
      <origin rpy="1.5707 0 0" xyz="0 0 0"/>
      <geometry>
        <mesh filename="meshes/collision/F0_base.stl"/>
      </geometry>
    </collision>
  </link>
  <gazebo reference="F1_base">
    <selfCollide>true</selfCollide>
  </gazebo>
  <link name="F1_J0_link">
    <inertial>
      <origin rpy="0 0 0" xyz="-0.00017293 -0.01537184 0.00956679"/>
      <mass value="0.13077995"/>
      <inertia ixx="0.00005895" ixy="0.00000007" ixz="0.00000064" iyy="0.00004702" iyz="-0.00000971" izz="0.00003911"/>
    </inertial>
    <visual>
      <origin rpy="0 0 0" xyz="0 0.077 0"/>
      <geometry>
        <mesh filename="meshes/F0_J0_link.dae"/>
      </geometry>
      <material name="">
        <color rgba="0.75294 0.75294 0.75294 1"/>
      </material>
    </visual>
    <collision>
      <origin rpy="0 0 0" xyz="0 0.077 0"/>
      <geometry>
        <mesh filename="meshes/collision/F0_J0_link.stl"/>
      </geometry>
    </collision>
  </link>
  <gazebo reference="F1_J0_link">
    <selfCollide>true</selfCollide>
  </gazebo>
  <joint name="F1_J0" type="revolute">
    <origin rpy="2.0944 0 0" xyz="0 -0.14073 -0.051327"/>
    <parent link="F1_base"/>
    <child link="F1_J0_link"/>
    <axis xyz="0 -1 0"/>
    <limit effort="1.5" lower="-0.8727" upper="0.8727" velocity="3.1415"/>
    <dynamics friction="0.001"/>
  </joint>
  <link name="F1_proximal">
    <inertial>
      <origin rpy="0 0 0" xyz="-0.00020256 0.0024322 0.02375091"/>
      <mass value="0.09614332"/>
      <inertia ixx="0.00004332" ixy="-0.00000017" ixz="-0.00000349" iyy="0.00004756" iyz="0.00000055" izz="0.00002008"/>
    </inertial>
    <visual>
      <origin rpy="0 0 0" xyz="0 0 0"/>
      <geometry>
        <mesh filename="meshes/F0_proximal.dae"/>
      </geometry>
      <material name="">
        <color rgba="0.75294 0.75294 0.75294 1"/>
      </material>
    </visual>
    <collision>
      <origin rpy="0 0 0" xyz="0 0 0"/>
      <geometry>
        <mesh filename="meshes/collision/F0_proximal.stl"/>
      </geometry>
    </collision>
  </link>
  <gazebo reference="F1_proximal">
    <selfCollide>true</selfCollide>
  </gazebo>
  <joint name="F1_J1" type="revolute">
    <origin rpy="0 0 0" xyz="0 0.0765883365730207 0.0299999999999999"/>
    <parent link="F1_J0_link"/>
    <child link="F1_proximal"/>
    <axis xyz="1 0 0"/>
    <limit effort="1.2" lower="-1.396" upper="0.785" velocity="3.1415"/>
    <dynamics friction="0.001"/>
  </joint>
  <link name="F1_middle">
    <inertial>
      <origin rpy="0 0 0" xyz="-0.00026744 -0.00004338 0.01669764"/>
      <mass value="0.05585897"/>
      <inertia ixx="0.00001447" ixy="-0.00000005" ixz="-0.00000004" iyy="0.00001686" iyz="-0.00000007" izz="0.00000973"/>
    </inertial>
    <visual>
      <origin rpy="0 0 0" xyz="0 0 0"/>
      <geometry>
        <mesh filename="meshes/F0_middle.dae"/>
      </geometry>
      <material name="">
        <color rgba="0.75294 0.75294 0.75294 1"/>
      </material>
    </visual>
    <collision>
      <origin rpy="0 0 0" xyz="0 0 0"/>
      <geometry>
        <mesh filename="meshes/collision/F0_middle.stl"/>
      </geometry>
    </collision>
  </link>
  <gazebo reference="F1_middle">
    <selfCollide>true</selfCollide>
  </gazebo>
  <joint name="F1_J2" type="revolute">
    <origin rpy="0 0 0" xyz="0 0 0.05"/>
    <parent link="F1_proximal"/>
    <child link="F1_middle"/>
    <axis xyz="1 0 0"/>
    <limit effort="0.7" lower="0" upper="1.396" velocity="3.1415"/>
    <dynamics friction="0.001"/>
  </joint>
  <link name="F1_distal">
    <inertial>
      <origin rpy="0 0 0" xyz="0.00084325 0.00164346 0.01482169"/>
      <mass value="0.02766365"/>
      <inertia ixx="0.0000051" ixy="0" ixz="0.00000028" iyy="0.00000506" iyz="-0.00000034" izz="0.00000198"/>
    </inertial>
    <visual>
      <origin rpy="0 0 0" xyz="0 0 0"/>
      <geometry>
        <mesh filename="meshes/F0_distal.dae"/>
      </geometry>
      <material name="">
        <color rgba="0.75294 0.75294 0.75294 1"/>
      </material>
    </visual>
    <collision>
      <origin rpy="0 0 0" xyz="0 0 0"/>
      <geometry>
        <mesh filename="meshes/collision/F0_distal.stl"/>
      </geometry>
    </collision>
  </link>
  <gazebo reference="F1_distal">
    <selfCollide>true</selfCollide>
  </gazebo>
  <joint name="F1_J3" type="revolute">
    <origin rpy="0 0 0" xyz="0 0 0.035"/>
    <parent link="F1_middle"/>
    <child link="F1_distal"/>
    <axis xyz="1 0 0"/>
    <limit effort="0.35" lower="-0.523" upper="1.485" velocity="3.1415"/>
    <dynamics friction="0.001"/>
  </joint>
  <link name="F1_tip"/>
  <joint name="F1_distal_tip" type="fixed">
    <parent link="F1_distal"/>
    <child link="F1_tip"/>
    <origin rpy="0 0 0" xyz="0 0.003 0.033"/>
  </joint>
  <!-- These transmissions are wrongly configured and fail to be loaded by the real robot -->
  <!-- We still need to define them in order to be able to launch the robot in simulation -->
  <transmission name="trans_F1_J0">
    <type>UnusedTransmission</type>
    <joint name="F1_J0">
      <hardwareInterface>hardware_interface/EffortJointInterface</hardwareInterface>
    </joint>
    <actuator name="F1_J0_motor">
      <!-- <hardwareInterface>hardware_interface/EffortJointInterface</hardwareInterface> -->
      <mechanicalReduction>1</mechanicalReduction>
    </actuator>
  </transmission>
  <transmission name="trans_F1_J1">
    <type>UnusedTransmission</type>
    <joint name="F1_J1">
      <hardwareInterface>hardware_interface/EffortJointInterface</hardwareInterface>
    </joint>
    <actuator name="F1_J1_motor">
      <!-- <hardwareInterface>hardware_interface/EffortJointInterface</hardwareInterface> -->
      <mechanicalReduction>1</mechanicalReduction>
    </actuator>
  </transmission>
  <transmission name="trans_F1_J2">
    <type>UnusedTransmission</type>
    <joint name="F1_J2">
      <hardwareInterface>hardware_interface/EffortJointInterface</hardwareInterface>
    </joint>
    <actuator name="F1_J2_motor">
      <!-- <hardwareInterface>hardware_interface/EffortJointInterface</hardwareInterface> -->
      <mechanicalReduction>1</mechanicalReduction>
    </actuator>
  </transmission>
  <transmission name="trans_F1_J3">
    <type>UnusedTransmission</type>
    <joint name="F1_J3">
      <hardwareInterface>hardware_interface/EffortJointInterface</hardwareInterface>
    </joint>
    <actuator name="F1_J3_motor">
      <!-- <hardwareInterface>hardware_interface/EffortJointInterface</hardwareInterface> -->
      <mechanicalReduction>1</mechanicalReduction>
    </actuator>
  </transmission>
  <joint name="world_joint_F2" type="fixed">
    <origin rpy="-1.5707 0 2.8159" xyz="-0.0384 -0.02870 0.017"/>
    <parent link="hand_base"/>
    <child link="F2_base"/>
  </joint>
  <link name="F2_base">
    <inertial>
      <origin rpy="0 0 0" xyz="0.00004454 0.00736569 0.08093736"/>
      <mass value="0.89937782"/>
      <inertia ixx="0.00186283" ixy="-0.00000176" ixz="-0.00000296" iyy="0.00181365" iyz="0.00004212" izz="0.00058221"/>
    </inertial>
    <visual>
      <origin rpy="1.5707 0 0" xyz="0 0 0"/>
      <geometry>
        <mesh filename="meshes/F0_base.dae"/>
      </geometry>
      <material name="">
        <color rgba="0.75294 0.75294 0.75294 1"/>
      </material>
    </visual>
    <collision>
      <origin rpy="1.5707 0 0" xyz="0 0 0"/>
      <geometry>
        <mesh filename="meshes/collision/F0_base.stl"/>
      </geometry>
    </collision>
  </link>
  <gazebo reference="F2_base">
    <selfCollide>true</selfCollide>
  </gazebo>
  <link name="F2_J0_link">
    <inertial>
      <origin rpy="0 0 0" xyz="-0.00017293 -0.01537184 0.00956679"/>
      <mass value="0.13077995"/>
      <inertia ixx="0.00005895" ixy="0.00000007" ixz="0.00000064" iyy="0.00004702" iyz="-0.00000971" izz="0.00003911"/>
    </inertial>
    <visual>
      <origin rpy="0 0 0" xyz="0 0.077 0"/>
      <geometry>
        <mesh filename="meshes/F0_J0_link.dae"/>
      </geometry>
      <material name="">
        <color rgba="0.75294 0.75294 0.75294 1"/>
      </material>
    </visual>
    <collision>
      <origin rpy="0 0 0" xyz="0 0.077 0"/>
      <geometry>
        <mesh filename="meshes/collision/F0_J0_link.stl"/>
      </geometry>
    </collision>
  </link>
  <gazebo reference="F2_J0_link">
    <selfCollide>true</selfCollide>
  </gazebo>
  <joint name="F2_J0" type="revolute">
    <origin rpy="2.0944 0 0" xyz="0 -0.14073 -0.051327"/>
    <parent link="F2_base"/>
    <child link="F2_J0_link"/>
    <axis xyz="0 -1 0"/>
    <limit effort="1.5" lower="-0.8727" upper="0.8727" velocity="3.1415"/>
    <dynamics friction="0.001"/>
  </joint>
  <link name="F2_proximal">
    <inertial>
      <origin rpy="0 0 0" xyz="-0.00020256 0.0024322 0.02375091"/>
      <mass value="0.09614332"/>
      <inertia ixx="0.00004332" ixy="-0.00000017" ixz="-0.00000349" iyy="0.00004756" iyz="0.00000055" izz="0.00002008"/>
    </inertial>
    <visual>
      <origin rpy="0 0 0" xyz="0 0 0"/>
      <geometry>
        <mesh filename="meshes/F0_proximal.dae"/>
      </geometry>
      <material name="">
        <color rgba="0.75294 0.75294 0.75294 1"/>
      </material>
    </visual>
    <collision>
      <origin rpy="0 0 0" xyz="0 0 0"/>
      <geometry>
        <mesh filename="meshes/collision/F0_proximal.stl"/>
      </geometry>
    </collision>
  </link>
  <gazebo reference="F2_proximal">
    <selfCollide>true</selfCollide>
  </gazebo>
  <joint name="F2_J1" type="revolute">
    <origin rpy="0 0 0" xyz="0 0.0765883365730207 0.0299999999999999"/>
    <parent link="F2_J0_link"/>
    <child link="F2_proximal"/>
    <axis xyz="1 0 0"/>
    <limit effort="1.2" lower="-1.396" upper="0.785" velocity="3.1415"/>
    <dynamics friction="0.001"/>
  </joint>
  <link name="F2_middle">
    <inertial>
      <origin rpy="0 0 0" xyz="-0.00026744 -0.00004338 0.01669764"/>
      <mass value="0.05585897"/>
      <inertia ixx="0.00001447" ixy="-0.00000005" ixz="-0.00000004" iyy="0.00001686" iyz="-0.00000007" izz="0.00000973"/>
    </inertial>
    <visual>
      <origin rpy="0 0 0" xyz="0 0 0"/>
      <geometry>
        <mesh filename="meshes/F0_middle.dae"/>
      </geometry>
      <material name="">
        <color rgba="0.75294 0.75294 0.75294 1"/>
      </material>
    </visual>
    <collision>
      <origin rpy="0 0 0" xyz="0 0 0"/>
      <geometry>
        <mesh filename="meshes/collision/F0_middle.stl"/>
      </geometry>
    </collision>
  </link>
  <gazebo reference="F2_middle">
    <selfCollide>true</selfCollide>
  </gazebo>
  <joint name="F2_J2" type="revolute">
    <origin rpy="0 0 0" xyz="0 0 0.05"/>
    <parent link="F2_proximal"/>
    <child link="F2_middle"/>
    <axis xyz="1 0 0"/>
    <limit effort="0.7" lower="0" upper="1.396" velocity="3.1415"/>
    <dynamics friction="0.001"/>
  </joint>
  <link name="F2_distal">
    <inertial>
      <origin rpy="0 0 0" xyz="0.00084325 0.00164346 0.01482169"/>
      <mass value="0.02766365"/>
      <inertia ixx="0.0000051" ixy="0" ixz="0.00000028" iyy="0.00000506" iyz="-0.00000034" izz="0.00000198"/>
    </inertial>
    <visual>
      <origin rpy="0 0 0" xyz="0 0 0"/>
      <geometry>
        <mesh filename="meshes/F0_distal.dae"/>
      </geometry>
      <material name="">
        <color rgba="0.75294 0.75294 0.75294 1"/>
      </material>
    </visual>
    <collision>
      <origin rpy="0 0 0" xyz="0 0 0"/>
      <geometry>
        <mesh filename="meshes/collision/F0_distal.stl"/>
      </geometry>
    </collision>
  </link>
  <gazebo reference="F2_distal">
    <selfCollide>true</selfCollide>
  </gazebo>
  <joint name="F2_J3" type="revolute">
    <origin rpy="0 0 0" xyz="0 0 0.035"/>
    <parent link="F2_middle"/>
    <child link="F2_distal"/>
    <axis xyz="1 0 0"/>
    <limit effort="0.35" lower="-0.523" upper="1.485" velocity="3.1415"/>
    <dynamics friction="0.001"/>
  </joint>
  <link name="F2_tip"/>
  <joint name="F2_distal_tip" type="fixed">
    <parent link="F2_distal"/>
    <child link="F2_tip"/>
    <origin rpy="0 0 0" xyz="0 0.003 0.033"/>
  </joint>
  <!-- These transmissions are wrongly configured and fail to be loaded by the real robot -->
  <!-- We still need to define them in order to be able to launch the robot in simulation -->
  <transmission name="trans_F2_J0">
    <type>UnusedTransmission</type>
    <joint name="F2_J0">
      <hardwareInterface>hardware_interface/EffortJointInterface</hardwareInterface>
    </joint>
    <actuator name="F2_J0_motor">
      <!-- <hardwareInterface>hardware_interface/EffortJointInterface</hardwareInterface> -->
      <mechanicalReduction>1</mechanicalReduction>
    </actuator>
  </transmission>
  <transmission name="trans_F2_J1">
    <type>UnusedTransmission</type>
    <joint name="F2_J1">
      <hardwareInterface>hardware_interface/EffortJointInterface</hardwareInterface>
    </joint>
    <actuator name="F2_J1_motor">
      <!-- <hardwareInterface>hardware_interface/EffortJointInterface</hardwareInterface> -->
      <mechanicalReduction>1</mechanicalReduction>
    </actuator>
  </transmission>
  <transmission name="trans_F2_J2">
    <type>UnusedTransmission</type>
    <joint name="F2_J2">
      <hardwareInterface>hardware_interface/EffortJointInterface</hardwareInterface>
    </joint>
    <actuator name="F2_J2_motor">
      <!-- <hardwareInterface>hardware_interface/EffortJointInterface</hardwareInterface> -->
      <mechanicalReduction>1</mechanicalReduction>
    </actuator>
  </transmission>
  <transmission name="trans_F2_J3">
    <type>UnusedTransmission</type>
    <joint name="F2_J3">
      <hardwareInterface>hardware_interface/EffortJointInterface</hardwareInterface>
    </joint>
    <actuator name="F2_J3_motor">
      <!-- <hardwareInterface>hardware_interface/EffortJointInterface</hardwareInterface> -->
      <mechanicalReduction>1</mechanicalReduction>
    </actuator>
  </transmission>
  <gazebo>
    <plugin filename="libgazebo_ros_control.so" name="gazebo_ros_control">
      <!--robotSimType>gazebo_ros_control/DefaultRobotHWSim</robotSimType-->
      <robotNamespace>hand_</robotNamespace>
      <robotParam>robot_description</robotParam>
    </plugin>
  </gazebo>
</robot>
