<robot name="e3_r3_hand" version="0">
    <!--Materials-->
    <material name="">
        <color rgba="0.898039215686 0.917647058824 0.929411764706 1"/>
        <luminescence value="0"/>
        <specularExponent value="40"/>
        <specularIntensity value="0.25"/>
    </material>
    <!--Links-->
    <robotProperties maxDepenetrationVelocity="10"/>
    <link name="hand_base">
        <inertial>
            <origin xyz="2.90761295962e-05 -0.0211317778292 0.0163403391887" rpy="0 -0 0"/>
            <mass value="3.2332007"/>
            <density value="-1"/>
            <inertia ixx="0.0433290741341" iyy="0.0123224835143" izz="0.0492239867848" ixy="-2.2444293836e-05" ixz="1.12809397454e-05" iyz="0.000624218907974"/>
        </inertial>
        <visual>
            <origin xyz="0 0 0" rpy="0 -0 0"/>
            <geometry>
                <mesh filename="meshes/Hand_Base.dae" scale="1 1 1"/>
                <settings planeNormalTolerance="0.949999988079" inflation="0" minThickness="9.99999974738e-05" maxVerts="32" mapResolution="0"/>
                <queryProperties useQueries="false"/>
            </geometry>
        </visual>
        <visual>
            <origin xyz="-0.0384 -0.0287 0.017" rpy="1.09553456669e-16 1.79997715539e-17 2.8159"/>
            <geometry>
                <mesh filename="meshes/F0_base.dae" scale="1 1 1"/>
                <settings planeNormalTolerance="0.949999988079" inflation="0" minThickness="9.99999974738e-05" maxVerts="32" mapResolution="0"/>
                <queryProperties useQueries="false"/>
            </geometry>
        </visual>
        <visual>
            <origin xyz="0.0384 -0.0287 0.017" rpy="1.09553456669e-16 -1.79997715539e-17 -2.8159"/>
            <geometry>
                <mesh filename="meshes/F0_base.dae" scale="1 1 1"/>
                <settings planeNormalTolerance="0.949999988079" inflation="0" minThickness="9.99999974738e-05" maxVerts="32" mapResolution="0"/>
                <queryProperties useQueries="false"/>
            </geometry>
        </visual>
        <visual>
            <origin xyz="0 0.05 0.017" rpy="0 -0 0"/>
            <geometry>
                <mesh filename="meshes/F0_base.dae" scale="1 1 1"/>
                <settings planeNormalTolerance="0.949999988079" inflation="0" minThickness="9.99999974738e-05" maxVerts="32" mapResolution="0"/>
                <queryProperties useQueries="false"/>
            </geometry>
        </visual>
        <collision>
            <origin xyz="0 0 0" rpy="0 -0 0"/>
            <geometry>
                <mesh filename="meshes/collision/Hand_Base.stl" scale="1 1 1"/>
                <settings planeNormalTolerance="0.949999988079" inflation="0" minThickness="9.99999974738e-05" maxVerts="32" mapResolution="0"/>
                <queryProperties useQueries="false"/>
            </geometry>
        </collision>
        <collision>
            <origin xyz="-0.0384 -0.0287 0.017" rpy="1.09553456669e-16 1.79997715539e-17 2.8159"/>
            <geometry>
                <mesh filename="meshes/collision/F0_base.stl" scale="1 1 1"/>
                <settings planeNormalTolerance="0.949999988079" inflation="0" minThickness="9.99999974738e-05" maxVerts="32" mapResolution="0"/>
                <queryProperties useQueries="false"/>
            </geometry>
        </collision>
        <collision>
            <origin xyz="0.0384 -0.0287 0.017" rpy="1.09553456669e-16 -1.79997715539e-17 -2.8159"/>
            <geometry>
                <mesh filename="meshes/collision/F0_base.stl" scale="1 1 1"/>
                <settings planeNormalTolerance="0.949999988079" inflation="0" minThickness="9.99999974738e-05" maxVerts="32" mapResolution="0"/>
                <queryProperties useQueries="false"/>
            </geometry>
        </collision>
        <collision>
            <origin xyz="0 0.05 0.017" rpy="0 -0 0"/>
            <geometry>
                <mesh filename="meshes/collision/F0_base.stl" scale="1 1 1"/>
                <settings planeNormalTolerance="0.949999988079" inflation="0" minThickness="9.99999974738e-05" maxVerts="32" mapResolution="0"/>
                <queryProperties useQueries="false"/>
            </geometry>
        </collision>
    </link>
    <link name="F2_middle">
        <inertial>
            <origin xyz="-0.00026744 -4.338e-05 0.01669764" rpy="0 -0 0"/>
            <mass value="0.05585897"/>
            <density value="-1"/>
            <inertia ixx="1.447e-05" iyy="1.686e-05" izz="9.73e-06" ixy="-5e-08" ixz="-4e-08" iyz="-7e-08"/>
        </inertial>
        <visual>
            <origin xyz="0 0 0" rpy="0 -0 0"/>
            <geometry>
                <mesh filename="meshes/F0_middle.dae" scale="1 1 1"/>
                <settings planeNormalTolerance="0.949999988079" inflation="0" minThickness="9.99999974738e-05" maxVerts="32" mapResolution="0"/>
                <queryProperties useQueries="false"/>
            </geometry>
        </visual>
        <collision>
            <origin xyz="0 0 0" rpy="0 -0 0"/>
            <geometry>
                <mesh filename="meshes/collision/F0_middle.stl" scale="1 1 1"/>
                <settings planeNormalTolerance="0.949999988079" inflation="0" minThickness="9.99999974738e-05" maxVerts="32" mapResolution="0"/>
                <queryProperties useQueries="false"/>
            </geometry>
        </collision>
    </link>
    <link name="F2_distal">
        <inertial>
            <origin xyz="0.00084325 0.00164346 0.01482169" rpy="0 -0 0"/>
            <mass value="0.02766365"/>
            <density value="-1"/>
            <inertia ixx="5.1e-06" iyy="5.06e-06" izz="1.98e-06" ixy="0" ixz="2.8e-07" iyz="-3.4e-07"/>
        </inertial>
        <visual>
            <origin xyz="0 0 0" rpy="0 -0 0"/>
            <geometry>
                <mesh filename="meshes/F0_distal.dae" scale="1 1 1"/>
                <settings planeNormalTolerance="0.949999988079" inflation="0" minThickness="9.99999974738e-05" maxVerts="32" mapResolution="0"/>
                <queryProperties useQueries="false"/>
            </geometry>
        </visual>
        <collision>
            <origin xyz="0 0 0" rpy="0 -0 0"/>
            <geometry>
                <mesh filename="meshes/collision/F0_distal.stl" scale="1 1 1"/>
                <settings planeNormalTolerance="0.949999988079" inflation="0" minThickness="9.99999974738e-05" maxVerts="32" mapResolution="0"/>
                <queryProperties useQueries="false"/>
            </geometry>
        </collision>
    </link>
    <link name="F0_J0_link">
        <inertial>
            <origin xyz="-0.00017293 -0.01537184 0.00956679" rpy="0 -0 0"/>
            <mass value="0.13077995"/>
            <density value="-1"/>
            <inertia ixx="5.895e-05" iyy="4.702e-05" izz="3.911e-05" ixy="7e-08" ixz="6.4e-07" iyz="-9.71e-06"/>
        </inertial>
        <visual>
            <origin xyz="0 0.077 0" rpy="0 -0 0"/>
            <geometry>
                <mesh filename="meshes/F0_J0_link.dae" scale="1 1 1"/>
                <settings planeNormalTolerance="0.949999988079" inflation="0" minThickness="9.99999974738e-05" maxVerts="32" mapResolution="0"/>
                <queryProperties useQueries="false"/>
            </geometry>
        </visual>
        <collision>
            <origin xyz="0 0.077 0" rpy="0 -0 0"/>
            <geometry>
                <mesh filename="meshes/collision/F0_J0_link.stl" scale="1 1 1"/>
                <settings planeNormalTolerance="0.949999988079" inflation="0" minThickness="9.99999974738e-05" maxVerts="32" mapResolution="0"/>
                <queryProperties useQueries="false"/>
            </geometry>
        </collision>
    </link>
    <link name="F0_proximal">
        <inertial>
            <origin xyz="-0.00020256 0.0024322 0.02375091" rpy="0 -0 0"/>
            <mass value="0.09614332"/>
            <density value="-1"/>
            <inertia ixx="4.332e-05" iyy="4.756e-05" izz="2.008e-05" ixy="-1.7e-07" ixz="-3.49e-06" iyz="5.5e-07"/>
        </inertial>
        <visual>
            <origin xyz="0 0 0" rpy="0 -0 0"/>
            <geometry>
                <mesh filename="meshes/F0_proximal.dae" scale="1 1 1"/>
                <settings planeNormalTolerance="0.949999988079" inflation="0" minThickness="9.99999974738e-05" maxVerts="32" mapResolution="0"/>
                <queryProperties useQueries="false"/>
            </geometry>
        </visual>
        <collision>
            <origin xyz="0 0 0" rpy="0 -0 0"/>
            <geometry>
                <mesh filename="meshes/collision/F0_proximal.stl" scale="1 1 1"/>
                <settings planeNormalTolerance="0.949999988079" inflation="0" minThickness="9.99999974738e-05" maxVerts="32" mapResolution="0"/>
                <queryProperties useQueries="false"/>
            </geometry>
        </collision>
    </link>
    <link name="F0_middle">
        <inertial>
            <origin xyz="-0.00026744 -4.338e-05 0.01669764" rpy="0 -0 0"/>
            <mass value="0.05585897"/>
            <density value="-1"/>
            <inertia ixx="1.447e-05" iyy="1.686e-05" izz="9.73e-06" ixy="-5e-08" ixz="-4e-08" iyz="-7e-08"/>
        </inertial>
        <visual>
            <origin xyz="0 0 0" rpy="0 -0 0"/>
            <geometry>
                <mesh filename="meshes/F0_middle.dae" scale="1 1 1"/>
                <settings planeNormalTolerance="0.949999988079" inflation="0" minThickness="9.99999974738e-05" maxVerts="32" mapResolution="0"/>
                <queryProperties useQueries="false"/>
            </geometry>
        </visual>
        <collision>
            <origin xyz="0 0 0" rpy="0 -0 0"/>
            <geometry>
                <mesh filename="meshes/collision/F0_middle.stl" scale="1 1 1"/>
                <settings planeNormalTolerance="0.949999988079" inflation="0" minThickness="9.99999974738e-05" maxVerts="32" mapResolution="0"/>
                <queryProperties useQueries="false"/>
            </geometry>
        </collision>
    </link>
    <link name="F0_distal">
        <inertial>
            <origin xyz="0.00084325 0.00164346 0.01482169" rpy="0 -0 0"/>
            <mass value="0.02766365"/>
            <density value="-1"/>
            <inertia ixx="5.1e-06" iyy="5.06e-06" izz="1.98e-06" ixy="0" ixz="2.8e-07" iyz="-3.4e-07"/>
        </inertial>
        <visual>
            <origin xyz="0 0 0" rpy="0 -0 0"/>
            <geometry>
                <mesh filename="meshes/F0_distal.dae" scale="1 1 1"/>
                <settings planeNormalTolerance="0.949999988079" inflation="0" minThickness="9.99999974738e-05" maxVerts="32" mapResolution="0"/>
                <queryProperties useQueries="false"/>
            </geometry>
        </visual>
        <collision>
            <origin xyz="0 0 0" rpy="0 -0 0"/>
            <geometry>
                <mesh filename="meshes/collision/F0_distal.stl" scale="1 1 1"/>
                <settings planeNormalTolerance="0.949999988079" inflation="0" minThickness="9.99999974738e-05" maxVerts="32" mapResolution="0"/>
                <queryProperties useQueries="false"/>
            </geometry>
        </collision>
    </link>
    <link name="F2_J0_link">
        <inertial>
            <origin xyz="-0.00017293 -0.01537184 0.00956679" rpy="0 -0 0"/>
            <mass value="0.13077995"/>
            <density value="-1"/>
            <inertia ixx="5.895e-05" iyy="4.702e-05" izz="3.911e-05" ixy="7e-08" ixz="6.4e-07" iyz="-9.71e-06"/>
        </inertial>
        <visual>
            <origin xyz="0 0.077 0" rpy="0 -0 0"/>
            <geometry>
                <mesh filename="meshes/F0_J0_link.dae" scale="1 1 1"/>
                <settings planeNormalTolerance="0.949999988079" inflation="0" minThickness="9.99999974738e-05" maxVerts="32" mapResolution="0"/>
                <queryProperties useQueries="false"/>
            </geometry>
        </visual>
        <collision>
            <origin xyz="0 0.077 0" rpy="0 -0 0"/>
            <geometry>
                <mesh filename="meshes/collision/F0_J0_link.stl" scale="1 1 1"/>
                <settings planeNormalTolerance="0.949999988079" inflation="0" minThickness="9.99999974738e-05" maxVerts="32" mapResolution="0"/>
                <queryProperties useQueries="false"/>
            </geometry>
        </collision>
    </link>
    <link name="F2_proximal">
        <inertial>
            <origin xyz="-0.00020256 0.0024322 0.02375091" rpy="0 -0 0"/>
            <mass value="0.09614332"/>
            <density value="-1"/>
            <inertia ixx="4.332e-05" iyy="4.756e-05" izz="2.008e-05" ixy="-1.7e-07" ixz="-3.49e-06" iyz="5.5e-07"/>
        </inertial>
        <visual>
            <origin xyz="0 0 0" rpy="0 -0 0"/>
            <geometry>
                <mesh filename="meshes/F0_proximal.dae" scale="1 1 1"/>
                <settings planeNormalTolerance="0.949999988079" inflation="0" minThickness="9.99999974738e-05" maxVerts="32" mapResolution="0"/>
                <queryProperties useQueries="false"/>
            </geometry>
        </visual>
        <collision>
            <origin xyz="0 0 0" rpy="0 -0 0"/>
            <geometry>
                <mesh filename="meshes/collision/F0_proximal.stl" scale="1 1 1"/>
                <settings planeNormalTolerance="0.949999988079" inflation="0" minThickness="9.99999974738e-05" maxVerts="32" mapResolution="0"/>
                <queryProperties useQueries="false"/>
            </geometry>
        </collision>
    </link>
    <link name="F1_J0_link">
        <inertial>
            <origin xyz="-0.00017293 -0.01537184 0.00956679" rpy="0 -0 0"/>
            <mass value="0.13077995"/>
            <density value="-1"/>
            <inertia ixx="5.895e-05" iyy="4.702e-05" izz="3.911e-05" ixy="7e-08" ixz="6.4e-07" iyz="-9.71e-06"/>
        </inertial>
        <visual>
            <origin xyz="0 0.077 0" rpy="0 -0 0"/>
            <geometry>
                <mesh filename="meshes/F0_J0_link.dae" scale="1 1 1"/>
                <settings planeNormalTolerance="0.949999988079" inflation="0" minThickness="9.99999974738e-05" maxVerts="32" mapResolution="0"/>
                <queryProperties useQueries="false"/>
            </geometry>
        </visual>
        <collision>
            <origin xyz="0 0.077 0" rpy="0 -0 0"/>
            <geometry>
                <mesh filename="meshes/collision/F0_J0_link.stl" scale="1 1 1"/>
                <settings planeNormalTolerance="0.949999988079" inflation="0" minThickness="9.99999974738e-05" maxVerts="32" mapResolution="0"/>
                <queryProperties useQueries="false"/>
            </geometry>
        </collision>
    </link>
    <link name="F1_proximal">
        <inertial>
            <origin xyz="-0.00020256 0.0024322 0.02375091" rpy="0 -0 0"/>
            <mass value="0.09614332"/>
            <density value="-1"/>
            <inertia ixx="4.332e-05" iyy="4.756e-05" izz="2.008e-05" ixy="-1.7e-07" ixz="-3.49e-06" iyz="5.5e-07"/>
        </inertial>
        <visual>
            <origin xyz="0 0 0" rpy="0 -0 0"/>
            <geometry>
                <mesh filename="meshes/F0_proximal.dae" scale="1 1 1"/>
                <settings planeNormalTolerance="0.949999988079" inflation="0" minThickness="9.99999974738e-05" maxVerts="32" mapResolution="0"/>
                <queryProperties useQueries="false"/>
            </geometry>
        </visual>
        <collision>
            <origin xyz="0 0 0" rpy="0 -0 0"/>
            <geometry>
                <mesh filename="meshes/collision/F0_proximal.stl" scale="1 1 1"/>
                <settings planeNormalTolerance="0.949999988079" inflation="0" minThickness="9.99999974738e-05" maxVerts="32" mapResolution="0"/>
                <queryProperties useQueries="false"/>
            </geometry>
        </collision>
    </link>
    <link name="F1_middle">
        <inertial>
            <origin xyz="-0.00026744 -4.338e-05 0.01669764" rpy="0 -0 0"/>
            <mass value="0.05585897"/>
            <density value="-1"/>
            <inertia ixx="1.447e-05" iyy="1.686e-05" izz="9.73e-06" ixy="-5e-08" ixz="-4e-08" iyz="-7e-08"/>
        </inertial>
        <visual>
            <origin xyz="0 0 0" rpy="0 -0 0"/>
            <geometry>
                <mesh filename="meshes/F0_middle.dae" scale="1 1 1"/>
                <settings planeNormalTolerance="0.949999988079" inflation="0" minThickness="9.99999974738e-05" maxVerts="32" mapResolution="0"/>
                <queryProperties useQueries="false"/>
            </geometry>
        </visual>
        <collision>
            <origin xyz="0 0 0" rpy="0 -0 0"/>
            <geometry>
                <mesh filename="meshes/collision/F0_middle.stl" scale="1 1 1"/>
                <settings planeNormalTolerance="0.949999988079" inflation="0" minThickness="9.99999974738e-05" maxVerts="32" mapResolution="0"/>
                <queryProperties useQueries="false"/>
            </geometry>
        </collision>
    </link>
    <link name="F1_distal">
        <inertial>
            <origin xyz="0.00084325 0.00164346 0.01482169" rpy="0 -0 0"/>
            <mass value="0.02766365"/>
            <density value="-1"/>
            <inertia ixx="5.1e-06" iyy="5.06e-06" izz="1.98e-06" ixy="0" ixz="2.8e-07" iyz="-3.4e-07"/>
        </inertial>
        <visual>
            <origin xyz="0 0 0" rpy="0 -0 0"/>
            <geometry>
                <mesh filename="meshes/F0_distal.dae" scale="1 1 1"/>
                <settings planeNormalTolerance="0.949999988079" inflation="0" minThickness="9.99999974738e-05" maxVerts="32" mapResolution="0"/>
                <queryProperties useQueries="false"/>
            </geometry>
        </visual>
        <collision>
            <origin xyz="0 0 0" rpy="0 -0 0"/>
            <geometry>
                <mesh filename="meshes/collision/F0_distal.stl" scale="1 1 1"/>
                <settings planeNormalTolerance="0.949999988079" inflation="0" minThickness="9.99999974738e-05" maxVerts="32" mapResolution="0"/>
                <queryProperties useQueries="false"/>
            </geometry>
        </collision>
    </link>
    <joint name="F2_J2" type="revolute">
        <child link="F2_middle"/>
        <parent link="F2_proximal"/>
        <origin xyz="0 0 0.05" rpy="0 -0 0"/>
        <linkTransform xyz="0 0 0.05" rpy="0 -0 0"/>
        <axis xyz="1 0 0"/>
        <limit lower="0" upper="1.396" effort="0.7" velocity="3.1415"/>
        <dynamics damping="0" stiffness="0" integral="0" friction="0.001" armature="0"/>
    </joint>
    <jointForceSensor value="true"/>
    <joint name="F2_J3" type="revolute">
        <child link="F2_distal"/>
        <parent link="F2_middle"/>
        <origin xyz="0 0 0.035" rpy="0 -0 0"/>
        <linkTransform xyz="0 0 0.035" rpy="0 -0 0"/>
        <axis xyz="1 0 0"/>
        <limit lower="-0.523" upper="1.485" effort="0.35" velocity="3.1415"/>
        <dynamics damping="0" stiffness="0" integral="0" friction="0.001" armature="0"/>
    </joint>
    <jointForceSensor value="true"/>
    <joint name="F0_J0" type="revolute">
        <child link="F0_J0_link"/>
        <parent link="hand_base"/>
        <origin xyz="0 -0.0013405558317 0.157725055182" rpy="0.5237 -0 0"/>
        <linkTransform xyz="0 -0.0013405558317 0.157725055182" rpy="0.5237 -0 0"/>
        <axis xyz="0 -1 0"/>
        <limit lower="-0.8727" upper="0.8727" effort="1.5" velocity="3.1415"/>
        <dynamics damping="0" stiffness="0" integral="0" friction="0.001" armature="0"/>
    </joint>
    <jointForceSensor value="true"/>
    <joint name="F0_J1" type="revolute">
        <child link="F0_proximal"/>
        <parent link="F0_J0_link"/>
        <origin xyz="0 0.076588336573 0.03" rpy="0 -0 0"/>
        <linkTransform xyz="0 0.076588336573 0.03" rpy="0 -0 0"/>
        <axis xyz="1 0 0"/>
        <limit lower="-1.396" upper="0.785" effort="1.2" velocity="3.1415"/>
        <dynamics damping="0" stiffness="0" integral="0" friction="0.001" armature="0"/>
    </joint>
    <jointForceSensor value="true"/>
    <joint name="F0_J2" type="revolute">
        <child link="F0_middle"/>
        <parent link="F0_proximal"/>
        <origin xyz="0 0 0.05" rpy="0 -0 0"/>
        <linkTransform xyz="0 0 0.05" rpy="0 -0 0"/>
        <axis xyz="1 0 0"/>
        <limit lower="0" upper="1.396" effort="0.7" velocity="3.1415"/>
        <dynamics damping="0" stiffness="0" integral="0" friction="0.001" armature="0"/>
    </joint>
    <jointForceSensor value="true"/>
    <joint name="F0_J3" type="revolute">
        <child link="F0_distal"/>
        <parent link="F0_middle"/>
        <origin xyz="0 0 0.035" rpy="0 -0 0"/>
        <linkTransform xyz="0 0 0.035" rpy="0 -0 0"/>
        <axis xyz="1 0 0"/>
        <limit lower="-0.523" upper="1.485" effort="0.35" velocity="3.1415"/>
        <dynamics damping="0" stiffness="0" integral="0" friction="0.001" armature="0"/>
    </joint>
    <jointForceSensor value="true"/>
    <joint name="F2_J0" type="revolute">
        <child link="F2_J0_link"/>
        <parent link="hand_base"/>
        <origin xyz="-0.0219728137711 0.0199415483482 0.157725055182" rpy="0.5237 -1.38777878078e-17 2.8159"/>
        <linkTransform xyz="-0.0219728137711 0.0199415483482 0.157725055182" rpy="0.5237 -1.38777878078e-17 2.8159"/>
        <axis xyz="0 -1 0"/>
        <limit lower="-0.8727" upper="0.8727" effort="1.5" velocity="3.1415"/>
        <dynamics damping="0" stiffness="0" integral="0" friction="0.001" armature="0"/>
    </joint>
    <jointForceSensor value="true"/>
    <joint name="F2_J1" type="revolute">
        <child link="F2_proximal"/>
        <parent link="F2_J0_link"/>
        <origin xyz="0 0.076588336573 0.03" rpy="0 -0 0"/>
        <linkTransform xyz="0 0.076588336573 0.03" rpy="0 -0 0"/>
        <axis xyz="1 0 0"/>
        <limit lower="-1.396" upper="0.785" effort="1.2" velocity="3.1415"/>
        <dynamics damping="0" stiffness="0" integral="0" friction="0.001" armature="0"/>
    </joint>
    <jointForceSensor value="true"/>
    <joint name="F1_J0" type="revolute">
        <child link="F1_J0_link"/>
        <parent link="hand_base"/>
        <origin xyz="0.0219728137711 0.0199415483482 0.157725055182" rpy="0.5237 1.38777878078e-17 -2.8159"/>
        <linkTransform xyz="0.0219728137711 0.0199415483482 0.157725055182" rpy="0.5237 1.38777878078e-17 -2.8159"/>
        <axis xyz="0 -1 0"/>
        <limit lower="-0.8727" upper="0.8727" effort="1.5" velocity="3.1415"/>
        <dynamics damping="0" stiffness="0" integral="0" friction="0.001" armature="0"/>
    </joint>
    <jointForceSensor value="true"/>
    <joint name="F1_J1" type="revolute">
        <child link="F1_proximal"/>
        <parent link="F1_J0_link"/>
        <origin xyz="0 0.076588336573 0.03" rpy="0 -0 0"/>
        <linkTransform xyz="0 0.076588336573 0.03" rpy="0 -0 0"/>
        <axis xyz="1 0 0"/>
        <limit lower="-1.396" upper="0.785" effort="1.2" velocity="3.1415"/>
        <dynamics damping="0" stiffness="0" integral="0" friction="0.001" armature="0"/>
    </joint>
    <jointForceSensor value="true"/>
    <joint name="F1_J2" type="revolute">
        <child link="F1_middle"/>
        <parent link="F1_proximal"/>
        <origin xyz="0 0 0.05" rpy="0 -0 0"/>
        <linkTransform xyz="0 0 0.05" rpy="0 -0 0"/>
        <axis xyz="1 0 0"/>
        <limit lower="0" upper="1.396" effort="0.7" velocity="3.1415"/>
        <dynamics damping="0" stiffness="0" integral="0" friction="0.001" armature="0"/>
    </joint>
    <joint name="F1_J3" type="revolute">
        <child link="F1_distal"/>
        <parent link="F1_middle"/>
        <origin xyz="0 0 0.035" rpy="0 -0 0"/>
        <linkTransform xyz="0 0 0.035" rpy="0 -0 0"/>
        <axis xyz="1 0 0"/>
        <limit lower="-0.523" upper="1.485" effort="0.35" velocity="3.1415"/>
        <dynamics damping="0" stiffness="0" integral="0" friction="0.001" armature="0"/>
    </joint>


    <depthCamera>
        <camera name="finger_depth_camera" type="depth" farClip="1" fovX="2.0944" fovY="0.785398" resX="128" resY="64"/>
    </depthCamera>

    <depthCameraInstance>
        <!--Camera names template: "{link_name}_camera_{camera_index_within_array}"
            Depth camera instances are expected to be arranged as camera arrays with shared origin and oriented to have
            aligned frustums, to be stitched vertically as a single seamless panoramic image,
            stacking top-down starting from the camera indexed 0-->

        <cameraInstance name="F0_distal_camera_0" camera="finger_depth_camera" link="F0_distal" xyz="0.0 -0.004 0.037" rpy="3.1415 0 0" />
        <cameraInstance name="F0_distal_camera_1" camera="finger_depth_camera" link="F0_distal" xyz="0.0 -0.004 0.037" rpy="3.927 0 0" />
        <cameraInstance name="F0_distal_camera_2" camera="finger_depth_camera" link="F0_distal" xyz="0.0 -0.004 0.037" rpy="4.712 0 0" />

        <cameraInstance name="F1_distal_camera_0" camera="finger_depth_camera" link="F1_distal" xyz="0.0 -0.004 0.037" rpy="3.1415 0 0" />
        <cameraInstance name="F1_distal_camera_1" camera="finger_depth_camera" link="F1_distal" xyz="0.0 -0.004 0.037" rpy="3.927 0 0" />
        <cameraInstance name="F1_distal_camera_2" camera="finger_depth_camera" link="F1_distal" xyz="0.0 -0.004 0.037" rpy="4.712 0 0" />

        <cameraInstance name="F2_distal_camera_0" camera="finger_depth_camera" link="F2_distal" xyz="0.0 -0.004 0.037" rpy="3.1415 0 0" />
        <cameraInstance name="F2_distal_camera_1" camera="finger_depth_camera" link="F2_distal" xyz="0.0 -0.004 0.037" rpy="3.927 0 0" />
        <cameraInstance name="F2_distal_camera_2" camera="finger_depth_camera" link="F2_distal" xyz="0.0 -0.004 0.037" rpy="4.712 0 0" />
    </depthCameraInstance>
</robot>
