<robot name="dexee_finger">
<!-- F0 Links -->
  <link name="F0_base">
    <inertial>
      <origin
        xyz="0.00004454 0.00736569 0.08093736"
        rpy="0 0 0" />
      <mass
        value="0.89937782" />
      <inertia
        ixx="0.00186283"
        ixy="-0.00000176"
        ixz="-0.00000296"
        iyy="0.00181365"
        iyz="0.00004212"
        izz="0.00058221" />
    </inertial>
    <visual>
      <origin
        xyz="0 0 0"
        rpy="0 0 0" />
      <geometry>
        <mesh
          filename="meshes/F0_base.dae" />
      </geometry>
      <material
        name="">
        <color
          rgba="0.75294 0.75294 0.75294 1" />
      </material>
    </visual>
    <collision>
      <origin
        xyz="0 0 0"
        rpy="0 0 0" />
      <geometry>
        <mesh
          filename="meshes/collision/F0_base.stl" />
      </geometry>
    </collision>
  </link>
  <link name="F0_J0_link">
    <inertial>
      <origin
        xyz="-0.00017293 -0.01537184 0.00956679"
        rpy="0 0 0" />
      <mass
        value="0.13077995" />
      <inertia
        ixx="0.00005895"
        ixy="0.00000007"
        ixz="0.00000064"
        iyy="0.00004702"
        iyz="-0.00000971"
        izz="0.00003911" />
    </inertial>
    <visual>
      <origin
        xyz="0 0 0"
        rpy="0 0 0" />
      <geometry>
        <mesh
          filename="meshes/F0_J0_link.dae" />
      </geometry>
      <material
        name="">
        <color
          rgba="0.75294 0.75294 0.75294 1" />
      </material>
    </visual>
    <collision>
      <origin
        xyz="0 0 0"
        rpy="0 0 0" />
      <geometry>
        <mesh
          filename="meshes/collision/F0_J0_link.stl" />
      </geometry>
    </collision>
  </link>
  <link name="F0_proximal">
    <inertial>
      <origin
        xyz="-0.00020256 0.0024322 0.02375091"
        rpy="0 0 0" />
      <mass
        value="0.09614332" />
      <inertia
        ixx="0.00004332"
        ixy="-0.00000017"
        ixz="-0.00000349"
        iyy="0.00004756"
        iyz="0.00000055"
        izz="0.00002008" />
    </inertial>
    <visual>
      <origin
        xyz="0 0 0"
        rpy="0 0 0" />
      <geometry>
        <mesh
          filename="meshes/F0_proximal.dae" />
      </geometry>
      <material
        name="">
        <color
          rgba="0.75294 0.75294 0.75294 1" />
      </material>
    </visual>
    <collision>
      <origin
        xyz="0 0 0"
        rpy="0 0 0" />
      <geometry>
        <mesh
          filename="meshes/collision/F0_proximal.stl" />
      </geometry>
    </collision>
  </link>
  <link name="F0_middle">
    <inertial>
      <origin
        xyz="-0.00026744 -0.00004338 0.01669764"
        rpy="0 0 0" />
      <mass
        value="0.05585897" />
      <inertia
        ixx="0.00001447"
        ixy="-0.00000005"
        ixz="-0.00000004"
        iyy="0.00001686"
        iyz="-0.00000007"
        izz="0.00000973" />
    </inertial>
    <visual>
      <origin
        xyz="0 0 0"
        rpy="0 0 0" />
      <geometry>
        <mesh
          filename="meshes/F0_middle.dae" />
      </geometry>
      <material
        name="">
        <color
          rgba="0.75294 0.75294 0.75294 1" />
      </material>
    </visual>
    <collision>
      <origin
        xyz="0 0 0"
        rpy="0 0 0" />
      <geometry>
        <mesh
          filename="meshes/collision/F0_middle.stl" />
      </geometry>
    </collision>
  </link>
  <link name="F0_distal">
    <inertial>
      <origin
        xyz="0.00084325 0.00164346 0.01482169"
        rpy="0 0 0" />
      <mass
        value="0.02766365" />
      <inertia
        ixx="0.0000051"
        ixy="0"
        ixz="0.00000028"
        iyy="0.00000506"
        iyz="-0.00000034"
        izz="0.00000198" />
    </inertial>
    <visual>
      <origin
        xyz="0 0 0"
        rpy="0 0 0" />
      <geometry>
        <mesh
          filename="meshes/F0_distal.dae" />
      </geometry>
      <material
        name="">
        <color
          rgba="0.75294 0.75294 0.75294 1" />
      </material>
    </visual>
    <collision>
      <origin
        xyz="0 0 0"
        rpy="0 0 0" />
      <geometry>
        <mesh
          filename="meshes/collision/F0_distal.stl" />
      </geometry>
    </collision>
  </link>

<!-- F0 Joints -->
  <joint name="F0_J0"
    type="revolute">
    <origin
      xyz="0 0.015 0.179"
      rpy="0.5236 0 0" />
    <parent
      link="F0_base" />
    <child
      link="F0_J0_link" />
    <axis
        xyz="0 -1 0" />
    <limit
        lower="-0.959"
        upper="0.959"
        effort="1.5"
        velocity="2" />
    <safety_controller
        soft_upper="0.95"
        soft_lower="-0.95"
        k_velocity="0" />
  </joint>
  <joint name="F0_J1"
    type="revolute">
    <origin
      xyz="0 0 0.03"
      rpy="-0.3491 0 0" />
    <parent
      link="F0_J0_link" />
    <child
      link="F0_proximal" />
    <axis
        xyz="1 0 0" />
    <limit
      lower="-1.396"
      upper="0.785"
      effort="1.2"
      velocity="2" />
    <safety_controller
      soft_upper="0.78"
      soft_lower="-1.39"
      k_velocity="0" />
  </joint>
  <joint name="F0_J2"
    type="revolute">
    <origin
      xyz="0 0 0.05"
      rpy="0 0 0" />
    <parent
      link="F0_proximal" />
    <child
      link="F0_middle" />
    <axis
        xyz="1 0 0" />
    <limit
        lower="0"
        upper="1.396"
        effort="0.7"
        velocity="2" />
    <safety_controller
        soft_upper="1.39"
        soft_lower="0"
        k_velocity="0" />
  </joint>
  <joint name="F0_J3"
    type="revolute">
    <origin
      xyz="0 0 0.035"
      rpy="0 0 0" />
    <parent
      link="F0_middle" />
    <child
      link="F0_distal" />
    <axis
        xyz="1 0 0" />
    <limit
        lower="-0.523"
        upper="1.485"
        effort="0.35" 
        velocity="0.2" />
    <safety_controller
        soft_upper="1.47"
        soft_lower="-0.51"
        k_velocity="0" />
  </joint>

</robot>
